Exception while resolving variable 'scores' in template 'reviews/company_view.html'.
Traceback (most recent call last):
  File "/home/tomek/env/lib/python3.6/site-packages/django/template/base.py", line 882, in _resolve_lookup
    current = current[bit]
KeyError: 'scores'

During handling of the above exception, another exception occurred:

Traceback (most recent call last):
  File "/home/tomek/env/lib/python3.6/site-packages/django/template/base.py", line 890, in _resolve_lookup
    current = getattr(current, bit)
AttributeError: 'dict' object has no attribute 'scores'

During handling of the above exception, another exception occurred:

Traceback (most recent call last):
  File "/home/tomek/env/lib/python3.6/site-packages/django/template/base.py", line 896, in _resolve_lookup
    current = current[int(bit)]
ValueError: invalid literal for int() with base 10: 'scores'

During handling of the above exception, another exception occurred:

Traceback (most recent call last):
  File "/home/tomek/env/lib/python3.6/site-packages/django/template/base.py", line 903, in _resolve_lookup
    (bit, current))  # missing attribute
django.template.base.VariableDoesNotExist: Failed lookup for key [scores] in "{'position__position': 'Dyrektor', 'position__location': 'Warszawa', 'position__department': None, 'position__employment_status': 'A', 'contract_type': 'A', 'currency': 'PLN', 'period': 'M', 'salary_min': 20000, 'salary_avg': 20000, 'salary_max': 20000, 'salary_count': 1, 'bonus_min': 50000, 'bonus_avg': 50000, 'bonus_max': 50000, 'bonus_count': 1, 'bonus_annual_min': 50000, 'bonus_annual_avg': 50000, 'bonus_annual_max': 50000, 'bonus_annual_count': 1, 'bonus_periods': ['R'], 'salary_object_list': [1]}"
Exception while resolving variable 'class' in template 'reviews/review_form.html'.
Traceback (most recent call last):
  File "/home/tomek/env/lib/python3.6/site-packages/django/template/base.py", line 882, in _resolve_lookup
    current = current[bit]
KeyError: 'class'

During handling of the above exception, another exception occurred:

Traceback (most recent call last):
  File "/home/tomek/env/lib/python3.6/site-packages/django/template/base.py", line 890, in _resolve_lookup
    current = getattr(current, bit)
AttributeError: 'dict' object has no attribute 'class'

During handling of the above exception, another exception occurred:

Traceback (most recent call last):
  File "/home/tomek/env/lib/python3.6/site-packages/django/template/base.py", line 896, in _resolve_lookup
    current = current[int(bit)]
ValueError: invalid literal for int() with base 10: 'class'

During handling of the above exception, another exception occurred:

Traceback (most recent call last):
  File "/home/tomek/env/lib/python3.6/site-packages/django/template/base.py", line 903, in _resolve_lookup
    (bit, current))  # missing attribute
django.template.base.VariableDoesNotExist: Failed lookup for key [class] in "{'maxlength': '100'}"
Exception while resolving variable 'class' in template 'reviews/review_form.html'.
Traceback (most recent call last):
  File "/home/tomek/env/lib/python3.6/site-packages/django/template/base.py", line 882, in _resolve_lookup
    current = current[bit]
KeyError: 'class'

During handling of the above exception, another exception occurred:

Traceback (most recent call last):
  File "/home/tomek/env/lib/python3.6/site-packages/django/template/base.py", line 890, in _resolve_lookup
    current = getattr(current, bit)
AttributeError: 'dict' object has no attribute 'class'

During handling of the above exception, another exception occurred:

Traceback (most recent call last):
  File "/home/tomek/env/lib/python3.6/site-packages/django/template/base.py", line 896, in _resolve_lookup
    current = current[int(bit)]
ValueError: invalid literal for int() with base 10: 'class'

During handling of the above exception, another exception occurred:

Traceback (most recent call last):
  File "/home/tomek/env/lib/python3.6/site-packages/django/template/base.py", line 903, in _resolve_lookup
    (bit, current))  # missing attribute
django.template.base.VariableDoesNotExist: Failed lookup for key [class] in "{'maxlength': '100'}"
Exception while resolving variable 'class' in template 'reviews/review_form.html'.
Traceback (most recent call last):
  File "/home/tomek/env/lib/python3.6/site-packages/django/template/base.py", line 882, in _resolve_lookup
    current = current[bit]
KeyError: 'class'

During handling of the above exception, another exception occurred:

Traceback (most recent call last):
  File "/home/tomek/env/lib/python3.6/site-packages/django/template/base.py", line 890, in _resolve_lookup
    current = getattr(current, bit)
AttributeError: 'dict' object has no attribute 'class'

During handling of the above exception, another exception occurred:

Traceback (most recent call last):
  File "/home/tomek/env/lib/python3.6/site-packages/django/template/base.py", line 896, in _resolve_lookup
    current = current[int(bit)]
ValueError: invalid literal for int() with base 10: 'class'

During handling of the above exception, another exception occurred:

Traceback (most recent call last):
  File "/home/tomek/env/lib/python3.6/site-packages/django/template/base.py", line 903, in _resolve_lookup
    (bit, current))  # missing attribute
django.template.base.VariableDoesNotExist: Failed lookup for key [class] in '{}'
Exception while resolving variable 'class' in template 'reviews/review_form.html'.
Traceback (most recent call last):
  File "/home/tomek/env/lib/python3.6/site-packages/django/template/base.py", line 882, in _resolve_lookup
    current = current[bit]
KeyError: 'class'

During handling of the above exception, another exception occurred:

Traceback (most recent call last):
  File "/home/tomek/env/lib/python3.6/site-packages/django/template/base.py", line 890, in _resolve_lookup
    current = getattr(current, bit)
AttributeError: 'dict' object has no attribute 'class'

During handling of the above exception, another exception occurred:

Traceback (most recent call last):
  File "/home/tomek/env/lib/python3.6/site-packages/django/template/base.py", line 896, in _resolve_lookup
    current = current[int(bit)]
ValueError: invalid literal for int() with base 10: 'class'

During handling of the above exception, another exception occurred:

Traceback (most recent call last):
  File "/home/tomek/env/lib/python3.6/site-packages/django/template/base.py", line 903, in _resolve_lookup
    (bit, current))  # missing attribute
django.template.base.VariableDoesNotExist: Failed lookup for key [class] in '{}'
Exception while resolving variable 'class' in template 'reviews/django_modified/radio_modified.html'.
Traceback (most recent call last):
  File "/home/tomek/env/lib/python3.6/site-packages/django/template/base.py", line 882, in _resolve_lookup
    current = current[bit]
KeyError: 'class'

During handling of the above exception, another exception occurred:

Traceback (most recent call last):
  File "/home/tomek/env/lib/python3.6/site-packages/django/template/base.py", line 890, in _resolve_lookup
    current = getattr(current, bit)
AttributeError: 'dict' object has no attribute 'class'

During handling of the above exception, another exception occurred:

Traceback (most recent call last):
  File "/home/tomek/env/lib/python3.6/site-packages/django/template/base.py", line 896, in _resolve_lookup
    current = current[int(bit)]
ValueError: invalid literal for int() with base 10: 'class'

During handling of the above exception, another exception occurred:

Traceback (most recent call last):
  File "/home/tomek/env/lib/python3.6/site-packages/django/template/base.py", line 903, in _resolve_lookup
    (bit, current))  # missing attribute
django.template.base.VariableDoesNotExist: Failed lookup for key [class] in "{'required': True, 'id': 'id_advancement'}"
Exception while resolving variable 'class' in template 'reviews/review_form.html'.
Traceback (most recent call last):
  File "/home/tomek/env/lib/python3.6/site-packages/django/template/base.py", line 882, in _resolve_lookup
    current = current[bit]
KeyError: 'class'

During handling of the above exception, another exception occurred:

Traceback (most recent call last):
  File "/home/tomek/env/lib/python3.6/site-packages/django/template/base.py", line 890, in _resolve_lookup
    current = getattr(current, bit)
AttributeError: 'dict' object has no attribute 'class'

During handling of the above exception, another exception occurred:

Traceback (most recent call last):
  File "/home/tomek/env/lib/python3.6/site-packages/django/template/base.py", line 896, in _resolve_lookup
    current = current[int(bit)]
ValueError: invalid literal for int() with base 10: 'class'

During handling of the above exception, another exception occurred:

Traceback (most recent call last):
  File "/home/tomek/env/lib/python3.6/site-packages/django/template/base.py", line 903, in _resolve_lookup
    (bit, current))  # missing attribute
django.template.base.VariableDoesNotExist: Failed lookup for key [class] in '{}'
Exception while resolving variable 'class' in template 'reviews/review_form.html'.
Traceback (most recent call last):
  File "/home/tomek/env/lib/python3.6/site-packages/django/template/base.py", line 882, in _resolve_lookup
    current = current[bit]
KeyError: 'class'

During handling of the above exception, another exception occurred:

Traceback (most recent call last):
  File "/home/tomek/env/lib/python3.6/site-packages/django/template/base.py", line 890, in _resolve_lookup
    current = getattr(current, bit)
AttributeError: 'dict' object has no attribute 'class'

During handling of the above exception, another exception occurred:

Traceback (most recent call last):
  File "/home/tomek/env/lib/python3.6/site-packages/django/template/base.py", line 896, in _resolve_lookup
    current = current[int(bit)]
ValueError: invalid literal for int() with base 10: 'class'

During handling of the above exception, another exception occurred:

Traceback (most recent call last):
  File "/home/tomek/env/lib/python3.6/site-packages/django/template/base.py", line 903, in _resolve_lookup
    (bit, current))  # missing attribute
django.template.base.VariableDoesNotExist: Failed lookup for key [class] in '{}'
Exception while resolving variable 'class' in template 'reviews/django_modified/radio_modified.html'.
Traceback (most recent call last):
  File "/home/tomek/env/lib/python3.6/site-packages/django/template/base.py", line 882, in _resolve_lookup
    current = current[bit]
KeyError: 'class'

During handling of the above exception, another exception occurred:

Traceback (most recent call last):
  File "/home/tomek/env/lib/python3.6/site-packages/django/template/base.py", line 890, in _resolve_lookup
    current = getattr(current, bit)
AttributeError: 'dict' object has no attribute 'class'

During handling of the above exception, another exception occurred:

Traceback (most recent call last):
  File "/home/tomek/env/lib/python3.6/site-packages/django/template/base.py", line 896, in _resolve_lookup
    current = current[int(bit)]
ValueError: invalid literal for int() with base 10: 'class'

During handling of the above exception, another exception occurred:

Traceback (most recent call last):
  File "/home/tomek/env/lib/python3.6/site-packages/django/template/base.py", line 903, in _resolve_lookup
    (bit, current))  # missing attribute
django.template.base.VariableDoesNotExist: Failed lookup for key [class] in "{'required': True, 'id': 'id_worklife'}"
Exception while resolving variable 'class' in template 'reviews/review_form.html'.
Traceback (most recent call last):
  File "/home/tomek/env/lib/python3.6/site-packages/django/template/base.py", line 882, in _resolve_lookup
    current = current[bit]
KeyError: 'class'

During handling of the above exception, another exception occurred:

Traceback (most recent call last):
  File "/home/tomek/env/lib/python3.6/site-packages/django/template/base.py", line 890, in _resolve_lookup
    current = getattr(current, bit)
AttributeError: 'dict' object has no attribute 'class'

During handling of the above exception, another exception occurred:

Traceback (most recent call last):
  File "/home/tomek/env/lib/python3.6/site-packages/django/template/base.py", line 896, in _resolve_lookup
    current = current[int(bit)]
ValueError: invalid literal for int() with base 10: 'class'

During handling of the above exception, another exception occurred:

Traceback (most recent call last):
  File "/home/tomek/env/lib/python3.6/site-packages/django/template/base.py", line 903, in _resolve_lookup
    (bit, current))  # missing attribute
django.template.base.VariableDoesNotExist: Failed lookup for key [class] in '{}'
Exception while resolving variable 'class' in template 'reviews/review_form.html'.
Traceback (most recent call last):
  File "/home/tomek/env/lib/python3.6/site-packages/django/template/base.py", line 882, in _resolve_lookup
    current = current[bit]
KeyError: 'class'

During handling of the above exception, another exception occurred:

Traceback (most recent call last):
  File "/home/tomek/env/lib/python3.6/site-packages/django/template/base.py", line 890, in _resolve_lookup
    current = getattr(current, bit)
AttributeError: 'dict' object has no attribute 'class'

During handling of the above exception, another exception occurred:

Traceback (most recent call last):
  File "/home/tomek/env/lib/python3.6/site-packages/django/template/base.py", line 896, in _resolve_lookup
    current = current[int(bit)]
ValueError: invalid literal for int() with base 10: 'class'

During handling of the above exception, another exception occurred:

Traceback (most recent call last):
  File "/home/tomek/env/lib/python3.6/site-packages/django/template/base.py", line 903, in _resolve_lookup
    (bit, current))  # missing attribute
django.template.base.VariableDoesNotExist: Failed lookup for key [class] in '{}'
Exception while resolving variable 'class' in template 'reviews/django_modified/radio_modified.html'.
Traceback (most recent call last):
  File "/home/tomek/env/lib/python3.6/site-packages/django/template/base.py", line 882, in _resolve_lookup
    current = current[bit]
KeyError: 'class'

During handling of the above exception, another exception occurred:

Traceback (most recent call last):
  File "/home/tomek/env/lib/python3.6/site-packages/django/template/base.py", line 890, in _resolve_lookup
    current = getattr(current, bit)
AttributeError: 'dict' object has no attribute 'class'

During handling of the above exception, another exception occurred:

Traceback (most recent call last):
  File "/home/tomek/env/lib/python3.6/site-packages/django/template/base.py", line 896, in _resolve_lookup
    current = current[int(bit)]
ValueError: invalid literal for int() with base 10: 'class'

During handling of the above exception, another exception occurred:

Traceback (most recent call last):
  File "/home/tomek/env/lib/python3.6/site-packages/django/template/base.py", line 903, in _resolve_lookup
    (bit, current))  # missing attribute
django.template.base.VariableDoesNotExist: Failed lookup for key [class] in "{'required': True, 'id': 'id_compensation'}"
Exception while resolving variable 'class' in template 'reviews/review_form.html'.
Traceback (most recent call last):
  File "/home/tomek/env/lib/python3.6/site-packages/django/template/base.py", line 882, in _resolve_lookup
    current = current[bit]
KeyError: 'class'

During handling of the above exception, another exception occurred:

Traceback (most recent call last):
  File "/home/tomek/env/lib/python3.6/site-packages/django/template/base.py", line 890, in _resolve_lookup
    current = getattr(current, bit)
AttributeError: 'dict' object has no attribute 'class'

During handling of the above exception, another exception occurred:

Traceback (most recent call last):
  File "/home/tomek/env/lib/python3.6/site-packages/django/template/base.py", line 896, in _resolve_lookup
    current = current[int(bit)]
ValueError: invalid literal for int() with base 10: 'class'

During handling of the above exception, another exception occurred:

Traceback (most recent call last):
  File "/home/tomek/env/lib/python3.6/site-packages/django/template/base.py", line 903, in _resolve_lookup
    (bit, current))  # missing attribute
django.template.base.VariableDoesNotExist: Failed lookup for key [class] in '{}'
Exception while resolving variable 'class' in template 'reviews/review_form.html'.
Traceback (most recent call last):
  File "/home/tomek/env/lib/python3.6/site-packages/django/template/base.py", line 882, in _resolve_lookup
    current = current[bit]
KeyError: 'class'

During handling of the above exception, another exception occurred:

Traceback (most recent call last):
  File "/home/tomek/env/lib/python3.6/site-packages/django/template/base.py", line 890, in _resolve_lookup
    current = getattr(current, bit)
AttributeError: 'dict' object has no attribute 'class'

During handling of the above exception, another exception occurred:

Traceback (most recent call last):
  File "/home/tomek/env/lib/python3.6/site-packages/django/template/base.py", line 896, in _resolve_lookup
    current = current[int(bit)]
ValueError: invalid literal for int() with base 10: 'class'

During handling of the above exception, another exception occurred:

Traceback (most recent call last):
  File "/home/tomek/env/lib/python3.6/site-packages/django/template/base.py", line 903, in _resolve_lookup
    (bit, current))  # missing attribute
django.template.base.VariableDoesNotExist: Failed lookup for key [class] in '{}'
Exception while resolving variable 'class' in template 'reviews/django_modified/radio_modified.html'.
Traceback (most recent call last):
  File "/home/tomek/env/lib/python3.6/site-packages/django/template/base.py", line 882, in _resolve_lookup
    current = current[bit]
KeyError: 'class'

During handling of the above exception, another exception occurred:

Traceback (most recent call last):
  File "/home/tomek/env/lib/python3.6/site-packages/django/template/base.py", line 890, in _resolve_lookup
    current = getattr(current, bit)
AttributeError: 'dict' object has no attribute 'class'

During handling of the above exception, another exception occurred:

Traceback (most recent call last):
  File "/home/tomek/env/lib/python3.6/site-packages/django/template/base.py", line 896, in _resolve_lookup
    current = current[int(bit)]
ValueError: invalid literal for int() with base 10: 'class'

During handling of the above exception, another exception occurred:

Traceback (most recent call last):
  File "/home/tomek/env/lib/python3.6/site-packages/django/template/base.py", line 903, in _resolve_lookup
    (bit, current))  # missing attribute
django.template.base.VariableDoesNotExist: Failed lookup for key [class] in "{'required': True, 'id': 'id_environment'}"
Exception while resolving variable 'class' in template 'reviews/review_form.html'.
Traceback (most recent call last):
  File "/home/tomek/env/lib/python3.6/site-packages/django/template/base.py", line 882, in _resolve_lookup
    current = current[bit]
KeyError: 'class'

During handling of the above exception, another exception occurred:

Traceback (most recent call last):
  File "/home/tomek/env/lib/python3.6/site-packages/django/template/base.py", line 890, in _resolve_lookup
    current = getattr(current, bit)
AttributeError: 'dict' object has no attribute 'class'

During handling of the above exception, another exception occurred:

Traceback (most recent call last):
  File "/home/tomek/env/lib/python3.6/site-packages/django/template/base.py", line 896, in _resolve_lookup
    current = current[int(bit)]
ValueError: invalid literal for int() with base 10: 'class'

During handling of the above exception, another exception occurred:

Traceback (most recent call last):
  File "/home/tomek/env/lib/python3.6/site-packages/django/template/base.py", line 903, in _resolve_lookup
    (bit, current))  # missing attribute
django.template.base.VariableDoesNotExist: Failed lookup for key [class] in '{}'
Exception while resolving variable 'class' in template 'reviews/review_form.html'.
Traceback (most recent call last):
  File "/home/tomek/env/lib/python3.6/site-packages/django/template/base.py", line 882, in _resolve_lookup
    current = current[bit]
KeyError: 'class'

During handling of the above exception, another exception occurred:

Traceback (most recent call last):
  File "/home/tomek/env/lib/python3.6/site-packages/django/template/base.py", line 890, in _resolve_lookup
    current = getattr(current, bit)
AttributeError: 'dict' object has no attribute 'class'

During handling of the above exception, another exception occurred:

Traceback (most recent call last):
  File "/home/tomek/env/lib/python3.6/site-packages/django/template/base.py", line 896, in _resolve_lookup
    current = current[int(bit)]
ValueError: invalid literal for int() with base 10: 'class'

During handling of the above exception, another exception occurred:

Traceback (most recent call last):
  File "/home/tomek/env/lib/python3.6/site-packages/django/template/base.py", line 903, in _resolve_lookup
    (bit, current))  # missing attribute
django.template.base.VariableDoesNotExist: Failed lookup for key [class] in '{}'
Exception while resolving variable 'class' in template 'reviews/django_modified/radio_modified.html'.
Traceback (most recent call last):
  File "/home/tomek/env/lib/python3.6/site-packages/django/template/base.py", line 882, in _resolve_lookup
    current = current[bit]
KeyError: 'class'

During handling of the above exception, another exception occurred:

Traceback (most recent call last):
  File "/home/tomek/env/lib/python3.6/site-packages/django/template/base.py", line 890, in _resolve_lookup
    current = getattr(current, bit)
AttributeError: 'dict' object has no attribute 'class'

During handling of the above exception, another exception occurred:

Traceback (most recent call last):
  File "/home/tomek/env/lib/python3.6/site-packages/django/template/base.py", line 896, in _resolve_lookup
    current = current[int(bit)]
ValueError: invalid literal for int() with base 10: 'class'

During handling of the above exception, another exception occurred:

Traceback (most recent call last):
  File "/home/tomek/env/lib/python3.6/site-packages/django/template/base.py", line 903, in _resolve_lookup
    (bit, current))  # missing attribute
django.template.base.VariableDoesNotExist: Failed lookup for key [class] in "{'required': True, 'id': 'id_overallscore'}"
Exception while resolving variable 'class' in template 'reviews/review_form.html'.
Traceback (most recent call last):
  File "/home/tomek/env/lib/python3.6/site-packages/django/template/base.py", line 882, in _resolve_lookup
    current = current[bit]
KeyError: 'class'

During handling of the above exception, another exception occurred:

Traceback (most recent call last):
  File "/home/tomek/env/lib/python3.6/site-packages/django/template/base.py", line 890, in _resolve_lookup
    current = getattr(current, bit)
AttributeError: 'dict' object has no attribute 'class'

During handling of the above exception, another exception occurred:

Traceback (most recent call last):
  File "/home/tomek/env/lib/python3.6/site-packages/django/template/base.py", line 896, in _resolve_lookup
    current = current[int(bit)]
ValueError: invalid literal for int() with base 10: 'class'

During handling of the above exception, another exception occurred:

Traceback (most recent call last):
  File "/home/tomek/env/lib/python3.6/site-packages/django/template/base.py", line 903, in _resolve_lookup
    (bit, current))  # missing attribute
django.template.base.VariableDoesNotExist: Failed lookup for key [class] in "{'cols': '40', 'rows': '10'}"
Exception while resolving variable 'class' in template 'reviews/review_form.html'.
Traceback (most recent call last):
  File "/home/tomek/env/lib/python3.6/site-packages/django/template/base.py", line 882, in _resolve_lookup
    current = current[bit]
KeyError: 'class'

During handling of the above exception, another exception occurred:

Traceback (most recent call last):
  File "/home/tomek/env/lib/python3.6/site-packages/django/template/base.py", line 890, in _resolve_lookup
    current = getattr(current, bit)
AttributeError: 'dict' object has no attribute 'class'

During handling of the above exception, another exception occurred:

Traceback (most recent call last):
  File "/home/tomek/env/lib/python3.6/site-packages/django/template/base.py", line 896, in _resolve_lookup
    current = current[int(bit)]
ValueError: invalid literal for int() with base 10: 'class'

During handling of the above exception, another exception occurred:

Traceback (most recent call last):
  File "/home/tomek/env/lib/python3.6/site-packages/django/template/base.py", line 903, in _resolve_lookup
    (bit, current))  # missing attribute
django.template.base.VariableDoesNotExist: Failed lookup for key [class] in "{'cols': '40', 'rows': '10'}"
Exception while resolving variable 'class' in template 'reviews/review_form.html'.
Traceback (most recent call last):
  File "/home/tomek/env/lib/python3.6/site-packages/django/template/base.py", line 882, in _resolve_lookup
    current = current[bit]
KeyError: 'class'

During handling of the above exception, another exception occurred:

Traceback (most recent call last):
  File "/home/tomek/env/lib/python3.6/site-packages/django/template/base.py", line 890, in _resolve_lookup
    current = getattr(current, bit)
AttributeError: 'dict' object has no attribute 'class'

During handling of the above exception, another exception occurred:

Traceback (most recent call last):
  File "/home/tomek/env/lib/python3.6/site-packages/django/template/base.py", line 896, in _resolve_lookup
    current = current[int(bit)]
ValueError: invalid literal for int() with base 10: 'class'

During handling of the above exception, another exception occurred:

Traceback (most recent call last):
  File "/home/tomek/env/lib/python3.6/site-packages/django/template/base.py", line 903, in _resolve_lookup
    (bit, current))  # missing attribute
django.template.base.VariableDoesNotExist: Failed lookup for key [class] in "{'cols': '40', 'rows': '10'}"
Exception while resolving variable 'class' in template 'reviews/review_form.html'.
Traceback (most recent call last):
  File "/home/tomek/env/lib/python3.6/site-packages/django/template/base.py", line 882, in _resolve_lookup
    current = current[bit]
KeyError: 'class'

During handling of the above exception, another exception occurred:

Traceback (most recent call last):
  File "/home/tomek/env/lib/python3.6/site-packages/django/template/base.py", line 890, in _resolve_lookup
    current = getattr(current, bit)
AttributeError: 'dict' object has no attribute 'class'

During handling of the above exception, another exception occurred:

Traceback (most recent call last):
  File "/home/tomek/env/lib/python3.6/site-packages/django/template/base.py", line 896, in _resolve_lookup
    current = current[int(bit)]
ValueError: invalid literal for int() with base 10: 'class'

During handling of the above exception, another exception occurred:

Traceback (most recent call last):
  File "/home/tomek/env/lib/python3.6/site-packages/django/template/base.py", line 903, in _resolve_lookup
    (bit, current))  # missing attribute
django.template.base.VariableDoesNotExist: Failed lookup for key [class] in "{'cols': '40', 'rows': '10'}"
Exception while resolving variable 'class' in template 'reviews/review_form.html'.
Traceback (most recent call last):
  File "/home/tomek/env/lib/python3.6/site-packages/django/template/base.py", line 882, in _resolve_lookup
    current = current[bit]
KeyError: 'class'

During handling of the above exception, another exception occurred:

Traceback (most recent call last):
  File "/home/tomek/env/lib/python3.6/site-packages/django/template/base.py", line 890, in _resolve_lookup
    current = getattr(current, bit)
AttributeError: 'dict' object has no attribute 'class'

During handling of the above exception, another exception occurred:

Traceback (most recent call last):
  File "/home/tomek/env/lib/python3.6/site-packages/django/template/base.py", line 896, in _resolve_lookup
    current = current[int(bit)]
ValueError: invalid literal for int() with base 10: 'class'

During handling of the above exception, another exception occurred:

Traceback (most recent call last):
  File "/home/tomek/env/lib/python3.6/site-packages/django/template/base.py", line 903, in _resolve_lookup
    (bit, current))  # missing attribute
django.template.base.VariableDoesNotExist: Failed lookup for key [class] in "{'cols': '40', 'rows': '10'}"
Exception while resolving variable 'class' in template 'reviews/review_form.html'.
Traceback (most recent call last):
  File "/home/tomek/env/lib/python3.6/site-packages/django/template/base.py", line 882, in _resolve_lookup
    current = current[bit]
KeyError: 'class'

During handling of the above exception, another exception occurred:

Traceback (most recent call last):
  File "/home/tomek/env/lib/python3.6/site-packages/django/template/base.py", line 890, in _resolve_lookup
    current = getattr(current, bit)
AttributeError: 'dict' object has no attribute 'class'

During handling of the above exception, another exception occurred:

Traceback (most recent call last):
  File "/home/tomek/env/lib/python3.6/site-packages/django/template/base.py", line 896, in _resolve_lookup
    current = current[int(bit)]
ValueError: invalid literal for int() with base 10: 'class'

During handling of the above exception, another exception occurred:

Traceback (most recent call last):
  File "/home/tomek/env/lib/python3.6/site-packages/django/template/base.py", line 903, in _resolve_lookup
    (bit, current))  # missing attribute
django.template.base.VariableDoesNotExist: Failed lookup for key [class] in "{'cols': '40', 'rows': '10'}"
Exception while resolving variable 'class' in template 'reviews/review_form.html'.
Traceback (most recent call last):
  File "/home/tomek/env/lib/python3.6/site-packages/django/template/base.py", line 882, in _resolve_lookup
    current = current[bit]
KeyError: 'class'

During handling of the above exception, another exception occurred:

Traceback (most recent call last):
  File "/home/tomek/env/lib/python3.6/site-packages/django/template/base.py", line 890, in _resolve_lookup
    current = getattr(current, bit)
AttributeError: 'dict' object has no attribute 'class'

During handling of the above exception, another exception occurred:

Traceback (most recent call last):
  File "/home/tomek/env/lib/python3.6/site-packages/django/template/base.py", line 896, in _resolve_lookup
    current = current[int(bit)]
ValueError: invalid literal for int() with base 10: 'class'

During handling of the above exception, another exception occurred:

Traceback (most recent call last):
  File "/home/tomek/env/lib/python3.6/site-packages/django/template/base.py", line 903, in _resolve_lookup
    (bit, current))  # missing attribute
django.template.base.VariableDoesNotExist: Failed lookup for key [class] in '{}'
Exception while resolving variable 'class' in template 'reviews/review_form.html'.
Traceback (most recent call last):
  File "/home/tomek/env/lib/python3.6/site-packages/django/template/base.py", line 882, in _resolve_lookup
    current = current[bit]
KeyError: 'class'

During handling of the above exception, another exception occurred:

Traceback (most recent call last):
  File "/home/tomek/env/lib/python3.6/site-packages/django/template/base.py", line 890, in _resolve_lookup
    current = getattr(current, bit)
AttributeError: 'dict' object has no attribute 'class'

During handling of the above exception, another exception occurred:

Traceback (most recent call last):
  File "/home/tomek/env/lib/python3.6/site-packages/django/template/base.py", line 896, in _resolve_lookup
    current = current[int(bit)]
ValueError: invalid literal for int() with base 10: 'class'

During handling of the above exception, another exception occurred:

Traceback (most recent call last):
  File "/home/tomek/env/lib/python3.6/site-packages/django/template/base.py", line 903, in _resolve_lookup
    (bit, current))  # missing attribute
django.template.base.VariableDoesNotExist: Failed lookup for key [class] in '{}'
